Workbook

Sheet FiberAxisProfiles_merged_eval_s
A1: method | B1: property | C1: epochs | D1: omega_0 | E1: n_eval | F1: mae_mean | G1: mae_std | H1: rmse_mean | I1: rmse_std | J1: property_std | K1: nmae = MAE/property_std
A2: knn10 | B2: AD | E2: 170 | F2: 0.000206705 | G2: 7.67679e-05 | H2: 0.000338842 | I2: 0.000142292 | J2: 0.000360099 | K2: 0.574022
A3: knn10 | B3: FA | E3: 170 | F3: 0.0886998 | G3: 0.0195235 | H3: 0.120522 | I3: 0.0270138 | J3: 0.130975 | K3: 0.677226
A4: knn10 | B4: FWF | E4: 170 | F4: 0.0784002 | G4: 0.0379585 | H4: 0.146831 | I4: 0.059705 | J4: 0.151559 | K4: 0.517293
A5: knn10 | B5: MD | E5: 170 | F5: 0.000142445 | G5: 7.49352e-05 | H5: 0.000276229 | I5: 0.000142289 | J5: 0.000294019 | K5: 0.484476
A6: knn10 | B6: NDI | E6: 170 | F6: 0.0473505 | G6: 0.0139062 | H6: 0.0689564 | I6: 0.0207746 | J6: 0.113809 | K6: 0.416053
A7: knn10 | B7: ODI | E7: 170 | F7: 0.0658958 | G7: 0.0215333 | H7: 0.0965452 | I7: 0.0391377 | J7: 0.0987012 | K7: 0.667629
A8: knn10 | B8: RD | E8: 170 | F8: 0.000159033 | G8: 7.27913e-05 | H8: 0.000279104 | I8: 0.000135073 | J8: 0.000291316 | K8: 0.545913 | M8: =AVERAGE(K2:K8) -> 0.55465886
A9: knn5 | B9: AD | E9: 170 | F9: 0.000213693 | G9: 7.83883e-05 | H9: 0.000355151 | I9: 0.000143231 | J9: 0.000360099 | K9: 0.593427
A10: knn5 | B10: FA | E10: 170 | F10: 0.0936086 | G10: 0.0200488 | H10: 0.127585 | I10: 0.0277817 | J10: 0.130975 | K10: 0.714705
A11: knn5 | B11: FWF | E11: 170 | F11: 0.080452 | G11: 0.0393337 | H11: 0.154768 | I11: 0.0616571 | J11: 0.151559 | K11: 0.530831
A12: knn5 | B12: MD | E12: 170 | F12: 0.000145046 | G12: 7.78962e-05 | H12: 0.000289797 | I12: 0.000145989 | J12: 0.000294019 | K12: 0.493321
A13: knn5 | B13: NDI | E13: 170 | F13: 0.0494632 | G13: 0.0144169 | H13: 0.0722719 | I13: 0.0216119 | J13: 0.113809 | K13: 0.434616
A14: knn5 | B14: ODI | E14: 170 | F14: 0.0688454 | G14: 0.0226176 | H14: 0.101606 | I14: 0.0404469 | J14: 0.0987012 | K14: 0.697514
A15: knn5 | B15: RD | E15: 170 | F15: 0.000163858 | G15: 7.61718e-05 | H15: 0.000293085 | I15: 0.000140187 | J15: 0.000291316 | K15: 0.562476 | M15: =AVERAGE(K9:K15) -> 0.57527
A16: linear | B16: AD | E16: 170 | F16: 0.000247226 | G16: 8.49276e-05 | H16: 0.000359534 | I16: 0.000160368 | J16: 0.000360099 | K16: 0.686549
A17: linear | B17: FA | E17: 170 | F17: 0.102242 | G17: 0.0182838 | H17: 0.130002 | I17: 0.0222638 | J17: 0.130975 | K17: 0.78062
A18: linear | B18: FWF | E18: 170 | F18: 0.10307 | G18: 0.0399368 | H18: 0.148104 | I18: 0.0739582 | J18: 0.151559 | K18: 0.68007
A19: linear | B19: MD | E19: 170 | F19: 0.000180086 | G19: 8.09678e-05 | H19: 0.000280233 | I19: 0.000159053 | J19: 0.000294019 | K19: 0.612497
A20: linear | B20: NDI | E20: 170 | F20: 0.075228 | G20: 0.0135058 | H20: 0.0930105 | I20: 0.0159175 | J20: 0.113809 | K20: 0.661004
A21: linear | B21: ODI | E21: 170 | F21: 0.0696487 | G21: 0.0197768 | H21: 0.0963555 | I21: 0.0379528 | J21: 0.0987012 | K21: 0.705652
A22: linear | B22: RD | E22: 170 | F22: 0.000181853 | G22: 7.79878e-05 | H22: 0.000279816 | I22: 0.000144775 | J22: 0.000291316 | K22: 0.624247 | M22: =AVERAGE(K16:K22) -> 0.67866271
A23: mean | B23: AD | E23: 170 | F23: 0.000242585 | G23: 8.46511e-05 | H23: 0.000361044 | I23: 0.000159555 | J23: 0.000360099 | K23: 0.673661
A24: mean | B24: FA | E24: 170 | F24: 0.103379 | G24: 0.0181969 | H24: 0.130081 | I24: 0.0221496 | J24: 0.130975 | K24: 0.789303
A25: mean | B25: FWF | E25: 170 | F25: 0.105024 | G25: 0.0396157 | H25: 0.14868 | I25: 0.0724126 | J25: 0.151559 | K25: 0.692957
A26: mean | B26: MD | E26: 170 | F26: 0.000176487 | G26: 8.04762e-05 | H26: 0.000281119 | I26: 0.000157752 | J26: 0.000294019 | K26: 0.600256
A27: mean | B27: NDI | E27: 170 | F27: 0.0854094 | G27: 0.0152267 | H27: 0.103602 | I27: 0.0190258 | J27: 0.113809 | K27: 0.750464
A28: mean | B28: ODI | E28: 170 | F28: 0.0721861 | G28: 0.0196622 | H28: 0.0984348 | I28: 0.0364882 | J28: 0.0987012 | K28: 0.73136
A29: mean | B29: RD | E29: 170 | F29: 0.000182711 | G29: 7.70175e-05 | H29: 0.000280248 | I29: 0.000143187 | J29: 0.000291316 | K29: 0.627191 | M29: =AVERAGE(K23:K29) -> 0.69502743
A30: median | B30: AD | E30: 170 | F30: 0.000234564 | G30: 9.30851e-05 | H30: 0.000361788 | I30: 0.000172308 | J30: 0.000360099 | K30: 0.651386
A31: median | B31: FA | E31: 170 | F31: 0.102771 | G31: 0.0193471 | H31: 0.130539 | I31: 0.0239488 | J31: 0.130975 | K31: 0.784662
A32: median | B32: FWF | E32: 170 | F32: 0.0818561 | G32: 0.0540075 | H32: 0.153578 | I32: 0.0900764 | J32: 0.151559 | K32: 0.540096
A33: median | B33: MD | E33: 170 | F33: 0.000163815 | G33: 8.89611e-05 | H33: 0.000277799 | I33: 0.000171716 | J33: 0.000294019 | K33: 0.557157
A34: median | B34: NDI | E34: 170 | F34: 0.0832368 | G34: 0.0200861 | H34: 0.106132 | I34: 0.0252994 | J34: 0.113809 | K34: 0.731374
A35: median | B35: ODI | E35: 170 | F35: 0.0696446 | G35: 0.0213995 | H35: 0.0993405 | I35: 0.0399254 | J35: 0.0987012 | K35: 0.705611
A36: median | B36: RD | E36: 170 | F36: 0.000175509 | G36: 8.21042e-05 | H36: 0.000277812 | I36: 0.000153617 | J36: 0.000291316 | K36: 0.602471 | M36: =AVERAGE(K30:K36) -> 0.653251
A37: rbf | B37: AD | E37: 170 | F37: 0.000222162 | G37: 8.3123e-05 | H37: 0.000375266 | I37: 0.000177333 | J37: 0.000360099 | K37: 0.616946
A38: rbf | B38: FA | E38: 170 | F38: 0.095262 | G38: 0.0219072 | H38: 0.130575 | I38: 0.0304823 | J38: 0.130975 | K38: 0.727328
A39: rbf | B39: FWF | E39: 170 | F39: 0.0914636 | G39: 0.038969 | H39: 0.166193 | I39: 0.0721302 | J39: 0.151559 | K39: 0.603487
A40: rbf | B40: MD | E40: 170 | F40: 0.00016838 | G40: 7.33395e-05 | H40: 0.00031346 | I40: 0.000147499 | J40: 0.000294019 | K40: 0.572685
...

Sheet Overall
A1: method | B1: NMAE all | C1: NMAE no MD, no FWF | D1: epochs | E1: omega_0
A2: knn10 | B2: =AVERAGE(FiberAxisProfiles_merged_eval_s!K2:K8) -> 0.55465886 | C2: =AVERAGE(FiberAxisProfiles_merged_eval_s!K2,FiberAxisProfiles_merged_eval_s!K3,FiberAxisProfiles_merged_eval_s!K6,FiberAxisProfiles_merged_eval_s!K7,FiberAxisProfiles_merged_eval_s!K8) -> 0.5761686
A3: knn5 | B3: =AVERAGE(FiberAxisProfiles_merged_eval_s!K9:K15) -> 0.57527 | C3: =AVERAGE(FiberAxisProfiles_merged_eval_s!K9,FiberAxisProfiles_merged_eval_s!K10,FiberAxisProfiles_merged_eval_s!K13,FiberAxisProfiles_merged_eval_s!K14,FiberAxisProfiles_merged_eval_s!K15) -> 0.6005476
A4: linear | B4: =AVERAGE(FiberAxisProfiles_merged_eval_s!K16:K22) -> 0.67866271 | C4: =AVERAGE(FiberAxisProfiles_merged_eval_s!K16,FiberAxisProfiles_merged_eval_s!K17,FiberAxisProfiles_merged_eval_s!K20,FiberAxisProfiles_merged_eval_s!K21,FiberAxisProfiles_merged_eval_s!K11) -> 0.6729312
A5: mean | B5: =AVERAGE(FiberAxisProfiles_merged_eval_s!K23:K29) -> 0.69502743 | C5: =AVERAGE(FiberAxisProfiles_merged_eval_s!K23,FiberAxisProfiles_merged_eval_s!K24,FiberAxisProfiles_merged_eval_s!K27,FiberAxisProfiles_merged_eval_s!K28,FiberAxisProfiles_merged_eval_s!K29) -> 0.7143958
A6: median | B6: =AVERAGE(FiberAxisProfiles_merged_eval_s!K30:K36) -> 0.653251 | C6: =AVERAGE(FiberAxisProfiles_merged_eval_s!K30,FiberAxisProfiles_merged_eval_s!K31,FiberAxisProfiles_merged_eval_s!K34,FiberAxisProfiles_merged_eval_s!K35,FiberAxisProfiles_merged_eval_s!K36) -> 0.6951008
A7: rbf | B7: =AVERAGE(FiberAxisProfiles_merged_eval_s!K37:K43) -> 0.62317843 | C7: =AVERAGE(FiberAxisProfiles_merged_eval_s!K37,FiberAxisProfiles_merged_eval_s!K38,FiberAxisProfiles_merged_eval_s!K41,FiberAxisProfiles_merged_eval_s!K42,FiberAxisProfiles_merged_eval_s!K43) -> 0.6372154
A8: siren | B8: =AVERAGE(FiberAxisProfiles_merged_eval_s!K121:K127) -> 0.50648457 | C8: =AVERAGE(FiberAxisProfiles_merged_eval_s!K121,FiberAxisProfiles_merged_eval_s!K122,FiberAxisProfiles_merged_eval_s!K125,FiberAxisProfiles_merged_eval_s!K126,FiberAxisProfiles_merged_eval_s!K127) -> 0.5196898 | D8: 200 | E8: 10
A23: knn10 | B23: AD | C23: 0.574022
A24: knn5 | B24: AD | C24: 0.593427
A25: linear | B25: AD | C25: 0.686549
A26: mean | B26: AD | C26: 0.673661
A27: median | B27: AD | C27: 0.651386
A28: rbf | B28: AD | C28: 0.616946
A29: siren | B29: AD | C29: 0.508278
A30: knn10 | B30: FA | C30: 0.677226
A31: knn5 | B31: FA | C31: 0.714705
A32: linear | B32: FA | C32: 0.78062
A33: mean | B33: FA | C33: 0.789303
A34: median | B34: FA | C34: 0.784662
... A71: siren | B71: RD | C71: 0.497735
